{"timestamp": "2025-09-11T23:00:26.083192", "level": "ERROR", "logger": "app.services.telemetry_llm_wrapper", "message": "LLM request failed: google/gemini-pro", "correlation_id": "136cd71c-c5d1-413c-a894-c219c32ce247", "module": "telemetry_llm_wrapper", "function": "generate", "line": 195, "exception": {"type": "Exception", "message": "Connection failed", "traceback": "Traceback (most recent call last):\n  File \"/Users/joshuafield/Documents/Ultra/app/services/telemetry_llm_wrapper.py\", line 137, in generate\n    result = await self.adapter.generate(prompt)\n             ^^^^^^^^^^^^^^^^^^^^^^^^^^^^^^^^^^^\n  File \"/opt/homebrew/Cellar/python@3.13/3.13.5/Frameworks/Python.framework/Versions/3.13/lib/python3.13/unittest/mock.py\", line 2321, in _execute_mock_call\n    raise effect\nException: Connection failed"}}
