{"timestamp": "2025-09-11T23:00:03.606556", "level": "ERROR", "logger": "app.services.telemetry_llm_wrapper", "message": "LLM request failed: google/gemini-pro", "correlation_id": "ade3cf3b-5b07-43ce-b368-58552c1f6e0e", "module": "telemetry_llm_wrapper", "function": "generate", "line": 195, "exception": {"type": "Exception", "message": "Connection failed", "traceback": "Traceback (most recent call last):\n  File \"/Users/joshuafield/Documents/Ultra/app/services/telemetry_llm_wrapper.py\", line 137, in generate\n    result = await self.adapter.generate(prompt)\n             ^^^^^^^^^^^^^^^^^^^^^^^^^^^^^^^^^^^\n  File \"/opt/homebrew/Cellar/python@3.13/3.13.5/Frameworks/Python.framework/Versions/3.13/lib/python3.13/unittest/mock.py\", line 2321, in _execute_mock_call\n    raise effect\nException: Connection failed"}}
